Workbook

Sheet Daily Ledger
A1: 🏨 RAYMITON HOTEL — Income & Expense Ledger
A2: Only fill: Date · Type · Category · Description · Total Charged · Amount Paid — Everything else calculates automatically
A4: Date | B4: Type | C4: Category | D4: Description | E4: Total Charged (₦) | F4: Amount Paid (₦) | G4: Balance Owed (₦) ⚙️ | H4: Status ⚙️ | I4: Running Balance (₦) ⚙️
A5: 46143 | B5: INCOME | C5: Rooms | D5: Lodge - Customer 1 (Room 1) Night | E5: 15000 | F5: 15000 | G5: =IF(ISBLANK(E5),"",E5-F5) -> 0 | H5: =IF(ISBLANK(E5),"", IF(UPPER(B5)="EXPENSE","Paid", IF(F5=0,"Not Paid", IF(F5<E5,"Part Payment", IF(F5=E5,"Paid","Overpaid"))))) -> Paid | I5: =IF(ISBLANK(F5),"",SUMIF(B$5:B5,"INCOME",F$5:F5)-SUMIF(B$5:B5,"EXPENSE",F$5:F5)) -> 15000
A6: 46143 | B6: INCOME | C6: Rooms | D6: Lodge - Customer 2 (Room 4) Short | E6: 5000 | F6: 5000 | G6: =IF(ISBLANK(E6),"",E6-F6) -> 0 | H6: =IF(ISBLANK(E6),"", IF(UPPER(B6)="EXPENSE","Paid", IF(F6=0,"Not Paid", IF(F6<E6,"Part Payment", IF(F6=E6,"Paid","Overpaid"))))) -> Paid | I6: =IF(ISBLANK(F6),"",SUMIF(B$5:B6,"INCOME",F$5:F6)-SUMIF(B$5:B6,"EXPENSE",F$5:F6)) -> 20000
A7: 46143 | B7: INCOME | C7: Rooms | D7: Lodge - (Pastor) (Room 4) | E7: 10000 | F7: 10000 | G7: =IF(ISBLANK(E7),"",E7-F7) -> 0 | H7: =IF(ISBLANK(E7),"", IF(UPPER(B7)="EXPENSE","Paid", IF(F7=0,"Not Paid", IF(F7<E7,"Part Payment", IF(F7=E7,"Paid","Overpaid"))))) -> Paid | I7: =IF(ISBLANK(F7),"",SUMIF(B$5:B7,"INCOME",F$5:F7)-SUMIF(B$5:B7,"EXPENSE",F$5:F7)) -> 30000
A8: 46143 | B8: EXPENSE | C8: Utilities | D8: SLTV Sub 1 Month | E8: 5000 | F8: 5000 | G8: =IF(ISBLANK(E8),"",E8-F8) -> 0 | H8: =IF(ISBLANK(E8),"", IF(UPPER(B8)="EXPENSE","Paid", IF(F8=0,"Not Paid", IF(F8<E8,"Part Payment", IF(F8=E8,"Paid","Overpaid"))))) -> Paid | I8: =IF(ISBLANK(F8),"",SUMIF(B$5:B8,"INCOME",F$5:F8)-SUMIF(B$5:B8,"EXPENSE",F$5:F8)) -> 25000
A9: 46143 | B9: EXPENSE | C9: Supplies | D9: Soap & Toiletries | E9: 500 | F9: 500 | G9: =IF(ISBLANK(E9),"",E9-F9) -> 0 | H9: =IF(ISBLANK(E9),"", IF(UPPER(B9)="EXPENSE","Paid", IF(F9=0,"Not Paid", IF(F9<E9,"Part Payment", IF(F9=E9,"Paid","Overpaid"))))) -> Paid | I9: =IF(ISBLANK(F9),"",SUMIF(B$5:B9,"INCOME",F$5:F9)-SUMIF(B$5:B9,"EXPENSE",F$5:F9)) -> 24500
A10: 46143 | B10: EXPENSE | C10: Utilities | D10: Gas Cylinder Fill - Generator | E10: 16000 | F10: 16000 | G10: =IF(ISBLANK(E10),"",E10-F10) -> 0 | H10: =IF(ISBLANK(E10),"", IF(UPPER(B10)="EXPENSE","Paid", IF(F10=0,"Not Paid", IF(F10<E10,"Part Payment", IF(F10=E10,"Paid","Overpaid"))))) -> Paid | I10: =IF(ISBLANK(F10),"",SUMIF(B$5:B10,"INCOME",F$5:F10)-SUMIF(B$5:B10,"EXPENSE",F$5:F10)) -> 8500
A11: 46143 | B11: EXPENSE | C11: Bar | D11: Packet of Bottle Water | E11: 2900 | F11: 2900 | G11: =IF(ISBLANK(E11),"",E11-F11) -> 0 | H11: =IF(ISBLANK(E11),"", IF(UPPER(B11)="EXPENSE","Paid", IF(F11=0,"Not Paid", IF(F11<E11,"Part Payment", IF(F11=E11,"Paid","Overpaid"))))) -> Paid | I11: =IF(ISBLANK(F11),"",SUMIF(B$5:B11,"INCOME",F$5:F11)-SUMIF(B$5:B11,"EXPENSE",F$5:F11)) -> 5600
A12: 46143 | B12: INCOME | C12: Bar | D12: Bottle of Water | E12: 500 | F12: 500 | G12: =IF(ISBLANK(E12),"",E12-F12) -> 0 | H12: =IF(ISBLANK(E12),"", IF(UPPER(B12)="EXPENSE","Paid", IF(F12=0,"Not Paid", IF(F12<E12,"Part Payment", IF(F12=E12,"Paid","Overpaid"))))) -> Paid | I12: =IF(ISBLANK(F12),"",SUMIF(B$5:B12,"INCOME",F$5:F12)-SUMIF(B$5:B12,"EXPENSE",F$5:F12)) -> 6100
A13: 46144 | B13: EXPENSE | C13: Utilities | D13: Gas fill 12kg | E13: 15000 | F13: 15000 | G13: =IF(ISBLANK(E13),"",E13-F13) -> 0 | H13: =IF(ISBLANK(E13),"", IF(UPPER(B13)="EXPENSE","Paid", IF(F13=0,"Not Paid", IF(F13<E13,"Part Payment", IF(F13=E13,"Paid","Overpaid"))))) -> Paid | I13: =IF(ISBLANK(F13),"",SUMIF(B$5:B13,"INCOME",F$5:F13)-SUMIF(B$5:B13,"EXPENSE",F$5:F13)) -> -8900
A14: 46144 | B14: EXPENSE | C14: Supplies | D14: Soap & Toiletries | E14: 750 | F14: 750 | G14: =IF(ISBLANK(E14),"",E14-F14) -> 0 | H14: =IF(ISBLANK(E14),"", IF(UPPER(B14)="EXPENSE","Paid", IF(F14=0,"Not Paid", IF(F14<E14,"Part Payment", IF(F14=E14,"Paid","Overpaid"))))) -> Paid | I14: =IF(ISBLANK(F14),"",SUMIF(B$5:B14,"INCOME",F$5:F14)-SUMIF(B$5:B14,"EXPENSE",F$5:F14)) -> -9650
A15: 46144 | B15: INCOME | C15: Bar | D15: Bottle of Water Small | E15: 400 | F15: 400 | G15: =IF(ISBLANK(E15),"",E15-F15) -> 0 | H15: =IF(ISBLANK(E15),"", IF(UPPER(B15)="EXPENSE","Paid", IF(F15=0,"Not Paid", IF(F15<E15,"Part Payment", IF(F15=E15,"Paid","Overpaid"))))) -> Paid | I15: =IF(ISBLANK(F15),"",SUMIF(B$5:B15,"INCOME",F$5:F15)-SUMIF(B$5:B15,"EXPENSE",F$5:F15)) -> -9250
A16: 46144 | B16: EXPENSE | C16: Bar | D16: Drinks (6 malts-33) (Half Crate Minera-33) | E16: 6800 | F16: 6800 | G16: =IF(ISBLANK(E16),"",E16-F16) -> 0 | H16: =IF(ISBLANK(E16),"", IF(UPPER(B16)="EXPENSE","Paid", IF(F16=0,"Not Paid", IF(F16<E16,"Part Payment", IF(F16=E16,"Paid","Overpaid"))))) -> Paid | I16: =IF(ISBLANK(F16),"",SUMIF(B$5:B16,"INCOME",F$5:F16)-SUMIF(B$5:B16,"EXPENSE",F$5:F16)) -> -16050
... A32: 46145 | B32: INCOME | C32: Bar | D32: Humble Drinks | E32: 5000 | F32: 5000 | G32: =IF(ISBLANK(E32),"",E32-F32) -> 0 | H32: =IF(ISBLANK(E32),"", IF(UPPER(B32)="EXPENSE","Paid", IF(F32=0,"Not Paid", IF(F32<E32,"Part Payment", IF(F32=E32,"Paid","Overpaid"))))) -> Paid | I32: =IF(ISBLANK(F32),"",SUMIF(B$5:B32,"INCOME",F$5:F32)-SUMIF(B$5:B32,"EXPENSE",F$5:F32)) -> 29650
G33: =IF(ISBLANK(E33),"",E33-F33) | H33: =IF(ISBLANK(E33),"", IF(UPPER(B33)="EXPENSE","Paid", IF(F33=0,"Not Paid", IF(F33<E33,"Part Payment", IF(F33=E33,"Paid","Overpaid"))))) | I33: =IF(ISBLANK(F33),"",SUMIF(B$5:B33,"INCOME",F$5:F33)-SUMIF(B$5:B33,"EXPENSE",F$5:F33))
G34: =IF(ISBLANK(E34),"",E34-F34) | H34: =IF(ISBLANK(E34),"", IF(UPPER(B34)="EXPENSE","Paid", IF(F34=0,"Not Paid", IF(F34<E34,"Part Payment", IF(F34=E34,"Paid","Overpaid"))))) | I34: =IF(ISBLANK(F34),"",SUMIF(B$5:B34,"INCOME",F$5:F34)-SUMIF(B$5:B34,"EXPENSE",F$5:F34))
G35: =IF(ISBLANK(E35),"",E35-F35) | H35: =IF(ISBLANK(E35),"", IF(UPPER(B35)="EXPENSE","Paid", IF(F35=0,"Not Paid", IF(F35<E35,"Part Payment", IF(F35=E35,"Paid","Overpaid"))))) | I35: =IF(ISBLANK(F35),"",SUMIF(B$5:B35,"INCOME",F$5:F35)-SUMIF(B$5:B35,"EXPENSE",F$5:F35))
G36: =IF(ISBLANK(E36),"",E36-F36) | H36: =IF(ISBLANK(E36),"", IF(UPPER(B36)="EXPENSE","Paid", IF(F36=0,"Not Paid", IF(F36<E36,"Part Payment", IF(F36=E36,"Paid","Overpaid"))))) | I36: =IF(ISBLANK(F36),"",SUMIF(B$5:B36,"INCOME",F$5:F36)-SUMIF(B$5:B36,"EXPENSE",F$5:F36))
G37: =IF(ISBLANK(E37),"",E37-F37) | H37: =IF(ISBLANK(E37),"", IF(UPPER(B37)="EXPENSE","Paid", IF(F37=0,"Not Paid", IF(F37<E37,"Part Payment", IF(F37=E37,"Paid","Overpaid"))))) | I37: =IF(ISBLANK(F37),"",SUMIF(B$5:B37,"INCOME",F$5:F37)-SUMIF(B$5:B37,"EXPENSE",F$5:F37))
G38: =IF(ISBLANK(E38),"",E38-F38) | H38: =IF(ISBLANK(E38),"", IF(UPPER(B38)="EXPENSE","Paid", IF(F38=0,"Not Paid", IF(F38<E38,"Part Payment", IF(F38=E38,"Paid","Overpaid"))))) | I38: =IF(ISBLANK(F38),"",SUMIF(B$5:B38,"INCOME",F$5:F38)-SUMIF(B$5:B38,"EXPENSE",F$5:F38))
G39: =IF(ISBLANK(E39),"",E39-F39) | H39: =IF(ISBLANK(E39),"", IF(UPPER(B39)="EXPENSE","Paid", IF(F39=0,"Not Paid", IF(F39<E39,"Part Payment", IF(F39=E39,"Paid","Overpaid"))))) | I39: =IF(ISBLANK(F39),"",SUMIF(B$5:B39,"INCOME",F$5:F39)-SUMIF(B$5:B39,"EXPENSE",F$5:F39))
G40: =IF(ISBLANK(E40),"",E40-F40) | H40: =IF(ISBLANK(E40),"", IF(UPPER(B40)="EXPENSE","Paid", IF(F40=0,"Not Paid", IF(F40<E40,"Part Payment", IF(F40=E40,"Paid","Overpaid"))))) | I40: =IF(ISBLANK(F40),"",SUMIF(B$5:B40,"INCOME",F$5:F40)-SUMIF(B$5:B40,"EXPENSE",F$5:F40))
G41: =IF(ISBLANK(E41),"",E41-F41) | H41: =IF(ISBLANK(E41),"", IF(UPPER(B41)="EXPENSE","Paid", IF(F41=0,"Not Paid", IF(F41<E41,"Part Payment", IF(F41=E41,"Paid","Overpaid"))))) | I41: =IF(ISBLANK(F41),"",SUMIF(B$5:B41,"INCOME",F$5:F41)-SUMIF(B$5:B41,"EXPENSE",F$5:F41))
G42: =IF(ISBLANK(E42),"",E42-F42) | H42: =IF(ISBLANK(E42),"", IF(UPPER(B42)="EXPENSE","Paid", IF(F42=0,"Not Paid", IF(F42<E42,"Part Payment", IF(F42=E42,"Paid","Overpaid"))))) | I42: =IF(ISBLANK(F42),"",SUMIF(B$5:B42,"INCOME",F$5:F42)-SUMIF(B$5:B42,"EXPENSE",F$5:F42))
G43: =IF(ISBLANK(E43),"",E43-F43) | H43: =IF(ISBLANK(E43),"", IF(UPPER(B43)="EXPENSE","Paid", IF(F43=0,"Not Paid", IF(F43<E43,"Part Payment", IF(F43=E43,"Paid","Overpaid"))))) | I43: =IF(ISBLANK(F43),"",SUMIF(B$5:B43,"INCOME",F$5:F43)-SUMIF(B$5:B43,"EXPENSE",F$5:F43))
G44: =IF(ISBLANK(E44),"",E44-F44) | H44: =IF(ISBLANK(E44),"", IF(UPPER(B44)="EXPENSE","Paid", IF(F44=0,"Not Paid", IF(F44<E44,"Part Payment", IF(F44=E44,"Paid","Overpaid"))))) | I44: =IF(ISBLANK(F44),"",SUMIF(B$5:B44,"INCOME",F$5:F44)-SUMIF(B$5:B44,"EXPENSE",F$5:F44))
... G304: =IF(ISBLANK(E304),"",E304-F304) | H304: =IF(ISBLANK(E304),"", IF(UPPER(B304)="EXPENSE","Paid", IF(F304=0,"Not Paid", IF(F304<E304,"Part Payment", IF(F304=E304,"Paid","Overpaid"))))) | I304: =IF(ISBLANK(F304),"",SUMIF(B$5:B304,"INCOME",F$5:F304)-SUMIF(B$5:B304,"EXPENSE",F$5:F304))
A306: SUMMARY
A307: TOTAL INCOME (Cash Received) | G307: =SUMIF(B5:B304,"INCOME",F5:F304) -> 102400
A308: TOTAL EXPENSES (Cash Paid Out) | G308: =SUMIF(B5:B304,"EXPENSE",F5:F304) -> 72750
A309: NET PROFIT / LOSS | G309: =I307-I308 -> 0
A310: ⚠️ TOTAL OUTSTANDING (Owed to Hotel) | G310: =SUMIF(B5:B304,"INCOME",G5:G304) -> 42500

Sheet Debtors
A1: 🏨 RAYMITON HOTEL — Who Owes Us Money
A2: Live from Daily Ledger — updates the moment you change Amount Paid on any row
A4: Date | B4: Description | C4: Total Charged (₦) | D4: Amount Paid (₦) | E4: Balance Owed (₦) | F4: Status
A5: ⚙️ LIVE VIEW: Formulas below auto-pull any INCOME row where Balance Owed > 0. Edit Amount Paid in Daily Ledger — this list updates instantly.
A6: {=IFERROR(INDEX('Daily Ledger'!$A$5:$A$304,IFERROR(SMALL(IF(('Daily Ledger'!$B$5:$B$304="INCOME")*('Daily Ledger'!$G$5:$G$304>0),ROW('Daily Ledger'!$B$5:$B$304)-4),1),"")),"")} -> 46144 | B6: {=IFERROR(INDEX('Daily Ledger'!$D$5:$D$304,IFERROR(SMALL(IF(('Daily Ledger'!$B$5:$B$304="INCOME")*('Daily Ledger'!$G$5:$G$304>0),ROW('Daily Ledger'!$B$5:$B$304)-4),1),"")),"")} -> 2 Malt 1 Fanta 2 bottle water(Jiro) | C6: {=IFERROR(INDEX('Daily Ledger'!$E$5:$E$304,IFERROR(SMALL(IF(('Daily Ledger'!$B$5:$B$304="INCOME")*('Daily Ledger'!$G$5:$G$304>0),ROW('Daily Ledger'!$B$5:$B$304)-4),1),"")),"")} -> 4500 | D6: {=IFERROR(INDEX('Daily Ledger'!$F$5:$F$304,IFERROR(SMALL(IF(('Daily Ledger'!$B$5:$B$304="INCOME")*('Daily Ledger'!$G$5:$G$304>0),ROW('Daily Ledger'!$B$5:$B$304)-4),1),"")),"")} -> 0 | E6: {=IFERROR(INDEX('Daily Ledger'!$G$5:$G$304,IFERROR(SMALL(IF(('Daily Ledger'!$B$5:$B$304="INCOME")*('Daily Ledger'!$G$5:$G$304>0),ROW('Daily Ledger'!$B$5:$B$304)-4),1),"")),"")} -> 4500 | F6: {=IFERROR(INDEX('Daily Ledger'!$H$5:$H$304,IFERROR(SMALL(IF(('Daily Ledger'!$B$5:$B$304="INCOME")*('Daily Ledger'!$G$5:$G$304>0),ROW('Daily Ledger'!$B$5:$B$304)-4),1),"")),"")} -> Not Paid
A7: {=IFERROR(INDEX('Daily Ledger'!$A$5:$A$304,IFERROR(SMALL(IF(('Daily Ledger'!$B$5:$B$304="INCOME")*('Daily Ledger'!$G$5:$G$304>0),ROW('Daily Ledger'!$B$5:$B$304)-4),2),"")),"")} -> 46145 | B7: {=IFERROR(INDEX('Daily Ledger'!$D$5:$D$304,IFERROR(SMALL(IF(('Daily Ledger'!$B$5:$B$304="INCOME")*('Daily Ledger'!$G$5:$G$304>0),ROW('Daily Ledger'!$B$5:$B$304)-4),2),"")),"")} -> Lodge Customer 1 (Night) Room 1 | C7: {=IFERROR(INDEX('Daily Ledger'!$E$5:$E$304,IFERROR(SMALL(IF(('Daily Ledger'!$B$5:$B$304="INCOME")*('Daily Ledger'!$G$5:$G$304>0),ROW('Daily Ledger'!$B$5:$B$304)-4),2),"")),"")} -> 15000 | D7: {=IFERROR(INDEX('Daily Ledger'!$F$5:$F$304,IFERROR(SMALL(IF(('Daily Ledger'!$B$5:$B$304="INCOME")*('Daily Ledger'!$G$5:$G$304>0),ROW('Daily Ledger'!$B$5:$B$304)-4),2),"")),"")} -> 5000 | E7: {=IFERROR(INDEX('Daily Ledger'!$G$5:$G$304,IFERROR(SMALL(IF(('Daily Ledger'!$B$5:$B$304="INCOME")*('Daily Ledger'!$G$5:$G$304>0),ROW('Daily Ledger'!$B$5:$B$304)-4),2),"")),"")} -> 10000 | F7: {=IFERROR(INDEX('Daily Ledger'!$H$5:$H$304,IFERROR(SMALL(IF(('Daily Ledger'!$B$5:$B$304="INCOME")*('Daily Ledger'!$G$5:$G$304>0),ROW('Daily Ledger'!$B$5:$B$304)-4),2),"")),"")} -> Part Payment
A8: {=IFERROR(INDEX('Daily Ledger'!$A$5:$A$304,IFERROR(SMALL(IF(('Daily Ledger'!$B$5:$B$304="INCOME")*('Daily Ledger'!$G$5:$G$304>0),ROW('Daily Ledger'!$B$5:$B$304)-4),3),"")),"")} -> 46145 | B8: {=IFERROR(INDEX('Daily Ledger'!$D$5:$D$304,IFERROR(SMALL(IF(('Daily Ledger'!$B$5:$B$304="INCOME")*('Daily Ledger'!$G$5:$G$304>0),ROW('Daily Ledger'!$B$5:$B$304)-4),3),"")),"")} -> Lodge Jiro (Night) Room 2 | C8: {=IFERROR(INDEX('Daily Ledger'!$E$5:$E$304,IFERROR(SMALL(IF(('Daily Ledger'!$B$5:$B$304="INCOME")*('Daily Ledger'!$G$5:$G$304>0),ROW('Daily Ledger'!$B$5:$B$304)-4),3),"")),"")} -> 15000 | D8: {=IFERROR(INDEX('Daily Ledger'!$F$5:$F$304,IFERROR(SMALL(IF(('Daily Ledger'!$B$5:$B$304="INCOME")*('Daily Ledger'!$G$5:$G$304>0),ROW('Daily Ledger'!$B$5:$B$304)-4),3),"")),"")} -> 0 | E8: {=IFERROR(INDEX('Daily Ledger'!$G$5:$G$304,IFERROR(SMALL(IF(('Daily Ledger'!$B$5:$B$304="INCOME")*('Daily Ledger'!$G$5:$G$304>0),ROW('Daily Ledger'!$B$5:$B$304)-4),3),"")),"")} -> 15000 | F8: {=IFERROR(INDEX('Daily Ledger'!$H$5:$H$304,IFERROR(SMALL(IF(('Daily Ledger'!$B$5:$B$304="INCOME")*('Daily Ledger'!$G$5:$G$304>0),ROW('Daily Ledger'!$B$5:$B$304)-4),3),"")),"")} -> Not Paid
A9: {=IFERROR(INDEX('Daily Ledger'!$A$5:$A$304,IFERROR(SMALL(IF(('Daily Ledger'!$B$5:$B$304="INCOME")*('Daily Ledger'!$G$5:$G$304>0),ROW('Daily Ledger'!$B$5:$B$304)-4),4),"")),"")} -> 46145 | B9: {=IFERROR(INDEX('Daily Ledger'!$D$5:$D$304,IFERROR(SMALL(IF(('Daily Ledger'!$B$5:$B$304="INCOME")*('Daily Ledger'!$G$5:$G$304>0),ROW('Daily Ledger'!$B$5:$B$304)-4),4),"")),"")} -> Lodge Let Love Lead (Night) Room 4 | C9: {=IFERROR(INDEX('Daily Ledger'!$E$5:$E$304,IFERROR(SMALL(IF(('Daily Ledger'!$B$5:$B$304="INCOME")*('Daily Ledger'!$G$5:$G$304>0),ROW('Daily Ledger'!$B$5:$B$304)-4),4),"")),"")} -> 8000 | D9: {=IFERROR(INDEX('Daily Ledger'!$F$5:$F$304,IFERROR(SMALL(IF(('Daily Ledger'!$B$5:$B$304="INCOME")*('Daily Ledger'!$G$5:$G$304>0),ROW('Daily Ledger'!$B$5:$B$304)-4),4),"")),"")} -> 0 | E9: {=IFERROR(INDEX('Daily Ledger'!$G$5:$G$304,IFERROR(SMALL(IF(('Daily Ledger'!$B$5:$B$304="INCOME")*('Daily Ledger'!$G$5:$G$304>0),ROW('Daily Ledger'!$B$5:$B$304)-4),4),"")),"")} -> 8000 | F9: {=IFERROR(INDEX('Daily Ledger'!$H$5:$H$304,IFERROR(SMALL(IF(('Daily Ledger'!$B$5:$B$304="INCOME")*('Daily Ledger'!$G$5:$G$304>0),ROW('Daily Ledger'!$B$5:$B$304)-4),4),"")),"")} -> Not Paid
A10: {=IFERROR(INDEX('Daily Ledger'!$A$5:$A$304,IFERROR(SMALL(IF(('Daily Ledger'!$B$5:$B$304="INCOME")*('Daily Ledger'!$G$5:$G$304>0),ROW('Daily Ledger'!$B$5:$B$304)-4),5),"")),"")} -> 46145 | B10: {=IFERROR(INDEX('Daily Ledger'!$D$5:$D$304,IFERROR(SMALL(IF(('Daily Ledger'!$B$5:$B$304="INCOME")*('Daily Ledger'!$G$5:$G$304>0),ROW('Daily Ledger'!$B$5:$B$304)-4),5),"")),"")} -> Lodge Captain (Short) Room 5 | C10: {=IFERROR(INDEX('Daily Ledger'!$E$5:$E$304,IFERROR(SMALL(IF(('Daily Ledger'!$B$5:$B$304="INCOME")*('Daily Ledger'!$G$5:$G$304>0),ROW('Daily Ledger'!$B$5:$B$304)-4),5),"")),"")} -> 5000 | D10: {=IFERROR(INDEX('Daily Ledger'!$F$5:$F$304,IFERROR(SMALL(IF(('Daily Ledger'!$B$5:$B$304="INCOME")*('Daily Ledger'!$G$5:$G$304>0),ROW('Daily Ledger'!$B$5:$B$304)-4),5),"")),"")} -> 0 | E10: {=IFERROR(INDEX('Daily Ledger'!$G$5:$G$304,IFERROR(SMALL(IF(('Daily Ledger'!$B$5:$B$304="INCOME")*('Daily Ledger'!$G$5:$G$304>0),ROW('Daily Ledger'!$B$5:$B$304)-4),5),"")),"")} -> 5000 | F10: {=IFERROR(INDEX('Daily Ledger'!$H$5:$H$304,IFERROR(SMALL(IF(('Daily Ledger'!$B$5:$B$304="INCOME")*('Daily Ledger'!$G$5:$G$304>0),ROW('Daily Ledger'!$B$5:$B$304)-4),5),"")),"")} -> Not Paid
A11: {=IFERROR(INDEX('Daily Ledger'!$A$5:$A$304,IFERROR(SMALL(IF(('Daily Ledger'!$B$5:$B$304="INCOME")*('Daily Ledger'!$G$5:$G$304>0),ROW('Daily Ledger'!$B$5:$B$304)-4),6),"")),"")} -> #REF! | B11: {=IFERROR(INDEX('Daily Ledger'!$D$5:$D$304,IFERROR(SMALL(IF(('Daily Ledger'!$B$5:$B$304="INCOME")*('Daily Ledger'!$G$5:$G$304>0),ROW('Daily Ledger'!$B$5:$B$304)-4),6),"")),"")} -> #REF! | C11: {=IFERROR(INDEX('Daily Ledger'!$E$5:$E$304,IFERROR(SMALL(IF(('Daily Ledger'!$B$5:$B$304="INCOME")*('Daily Ledger'!$G$5:$G$304>0),ROW('Daily Ledger'!$B$5:$B$304)-4),6),"")),"")} -> #REF! | D11: {=IFERROR(INDEX('Daily Ledger'!$F$5:$F$304,IFERROR(SMALL(IF(('Daily Ledger'!$B$5:$B$304="INCOME")*('Daily Ledger'!$G$5:$G$304>0),ROW('Daily Ledger'!$B$5:$B$304)-4),6),"")),"")} -> #REF! | E11: {=IFERROR(INDEX('Daily Ledger'!$G$5:$G$304,IFERROR(SMALL(IF(('Daily Ledger'!$B$5:$B$304="INCOME")*('Daily Ledger'!$G$5:$G$304>0),ROW('Daily Ledger'!$B$5:$B$304)-4),6),"")),"")} -> #REF! | F11: {=IFERROR(INDEX('Daily Ledger'!$H$5:$H$304,IFERROR(SMALL(IF(('Daily Ledger'!$B$5:$B$304="INCOME")*('Daily Ledger'!$G$5:$G$304>0),ROW('Daily Ledger'!$B$5:$B$304)-4),6),"")),"")} -> #REF!
A12: {=IFERROR(INDEX('Daily Ledger'!$A$5:$A$304,IFERROR(SMALL(IF(('Daily Ledger'!$B$5:$B$304="INCOME")*('Daily Ledger'!$G$5:$G$304>0),ROW('Daily Ledger'!$B$5:$B$304)-4),7),"")),"")} -> #REF! | B12: {=IFERROR(INDEX('Daily Ledger'!$D$5:$D$304,IFERROR(SMALL(IF(('Daily Ledger'!$B$5:$B$304="INCOME")*('Daily Ledger'!$G$5:$G$304>0),ROW('Daily Ledger'!$B$5:$B$304)-4),7),"")),"")} -> #REF! | C12: {=IFERROR(INDEX('Daily Ledger'!$E$5:$E$304,IFERROR(SMALL(IF(('Daily Ledger'!$B$5:$B$304="INCOME")*('Daily Ledger'!$G$5:$G$304>0),ROW('Daily Ledger'!$B$5:$B$304)-4),7),"")),"")} -> #REF! | D12: {=IFERROR(INDEX('Daily Ledger'!$F$5:$F$304,IFERROR(SMALL(IF(('Daily Ledger'!$B$5:$B$304="INCOME")*('Daily Ledger'!$G$5:$G$304>0),ROW('Daily Ledger'!$B$5:$B$304)-4),7),"")),"")} -> #REF! | E12: {=IFERROR(INDEX('Daily Ledger'!$G$5:$G$304,IFERROR(SMALL(IF(('Daily Ledger'!$B$5:$B$304="INCOME")*('Daily Ledger'!$G$5:$G$304>0),ROW('Daily Ledger'!$B$5:$B$304)-4),7),"")),"")} -> #REF! | F12: {=IFERROR(INDEX('Daily Ledger'!$H$5:$H$304,IFERROR(SMALL(IF(('Daily Ledger'!$B$5:$B$304="INCOME")*('Daily Ledger'!$G$5:$G$304>0),ROW('Daily Ledger'!$B$5:$B$304)-4),7),"")),"")} -> #REF!
A13: {=IFERROR(INDEX('Daily Ledger'!$A$5:$A$304,IFERROR(SMALL(IF(('Daily Ledger'!$B$5:$B$304="INCOME")*('Daily Ledger'!$G$5:$G$304>0),ROW('Daily Ledger'!$B$5:$B$304)-4),8),"")),"")} -> #REF! | B13: {=IFERROR(INDEX('Daily Ledger'!$D$5:$D$304,IFERROR(SMALL(IF(('Daily Ledger'!$B$5:$B$304="INCOME")*('Daily Ledger'!$G$5:$G$304>0),ROW('Daily Ledger'!$B$5:$B$304)-4),8),"")),"")} -> #REF! | C13: {=IFERROR(INDEX('Daily Ledger'!$E$5:$E$304,IFERROR(SMALL(IF(('Daily Ledger'!$B$5:$B$304="INCOME")*('Daily Ledger'!$G$5:$G$304>0),ROW('Daily Ledger'!$B$5:$B$304)-4),8),"")),"")} -> #REF! | D13: {=IFERROR(INDEX('Daily Ledger'!$F$5:$F$304,IFERROR(SMALL(IF(('Daily Ledger'!$B$5:$B$304="INCOME")*('Daily Ledger'!$G$5:$G$304>0),ROW('Daily Ledger'!$B$5:$B$304)-4),8),"")),"")} -> #REF! | E13: {=IFERROR(INDEX('Daily Ledger'!$G$5:$G$304,IFERROR(SMALL(IF(('Daily Ledger'!$B$5:$B$304="INCOME")*('Daily Ledger'!$G$5:$G$304>0),ROW('Daily Ledger'!$B$5:$B$304)-4),8),"")),"")} -> #REF! | F13: {=IFERROR(INDEX('Daily Ledger'!$H$5:$H$304,IFERROR(SMALL(IF(('Daily Ledger'!$B$5:$B$304="INCOME")*('Daily Ledger'!$G$5:$G$304>0),ROW('Daily Ledger'!$B$5:$B$304)-4),8),"")),"")} -> #REF!
A14: {=IFERROR(INDEX('Daily Ledger'!$A$5:$A$304,IFERROR(SMALL(IF(('Daily Ledger'!$B$5:$B$304="INCOME")*('Daily Ledger'!$G$5:$G$304>0),ROW('Daily Ledger'!$B$5:$B$304)-4),9),"")),"")} -> #REF! | B14: {=IFERROR(INDEX('Daily Ledger'!$D$5:$D$304,IFERROR(SMALL(IF(('Daily Ledger'!$B$5:$B$304="INCOME")*('Daily Ledger'!$G$5:$G$304>0),ROW('Daily Ledger'!$B$5:$B$304)-4),9),"")),"")} -> #REF! | C14: {=IFERROR(INDEX('Daily Ledger'!$E$5:$E$304,IFERROR(SMALL(IF(('Daily Ledger'!$B$5:$B$304="INCOME")*('Daily Ledger'!$G$5:$G$304>0),ROW('Daily Ledger'!$B$5:$B$304)-4),9),"")),"")} -> #REF! | D14: {=IFERROR(INDEX('Daily Ledger'!$F$5:$F$304,IFERROR(SMALL(IF(('Daily Ledger'!$B$5:$B$304="INCOME")*('Daily Ledger'!$G$5:$G$304>0),ROW('Daily Ledger'!$B$5:$B$304)-4),9),"")),"")} -> #REF! | E14: {=IFERROR(INDEX('Daily Ledger'!$G$5:$G$304,IFERROR(SMALL(IF(('Daily Ledger'!$B$5:$B$304="INCOME")*('Daily Ledger'!$G$5:$G$304>0),ROW('Daily Ledger'!$B$5:$B$304)-4),9),"")),"")} -> #REF! | F14: {=IFERROR(INDEX('Daily Ledger'!$H$5:$H$304,IFERROR(SMALL(IF(('Daily Ledger'!$B$5:$B$304="INCOME")*('Daily Ledger'!$G$5:$G$304>0),ROW('Daily Ledger'!$B$5:$B$304)-4),9),"")),"")} -> #REF!
A15: {=IFERROR(INDEX('Daily Ledger'!$A$5:$A$304,IFERROR(SMALL(IF(('Daily Ledger'!$B$5:$B$304="INCOME")*('Daily Ledger'!$G$5:$G$304>0),ROW('Daily Ledger'!$B$5:$B$304)-4),10),"")),"")} -> #REF! | B15: {=IFERROR(INDEX('Daily Ledger'!$D$5:$D$304,IFERROR(SMALL(IF(('Daily Ledger'!$B$5:$B$304="INCOME")*('Daily Ledger'!$G$5:$G$304>0),ROW('Daily Ledger'!$B$5:$B$304)-4),10),"")),"")} -> #REF! | C15: {=IFERROR(INDEX('Daily Ledger'!$E$5:$E$304,IFERROR(SMALL(IF(('Daily Ledger'!$B$5:$B$304="INCOME")*('Daily Ledger'!$G$5:$G$304>0),ROW('Daily Ledger'!$B$5:$B$304)-4),10),"")),"")} -> #REF! | D15: {=IFERROR(INDEX('Daily Ledger'!$F$5:$F$304,IFERROR(SMALL(IF(('Daily Ledger'!$B$5:$B$304="INCOME")*('Daily Ledger'!$G$5:$G$304>0),ROW('Daily Ledger'!$B$5:$B$304)-4),10),"")),"")} -> #REF! | E15: {=IFERROR(INDEX('Daily Ledger'!$G$5:$G$304,IFERROR(SMALL(IF(('Daily Ledger'!$B$5:$B$304="INCOME")*('Daily Ledger'!$G$5:$G$304>0),ROW('Daily Ledger'!$B$5:$B$304)-4),10),"")),"")} -> #REF! | F15: {=IFERROR(INDEX('Daily Ledger'!$H$5:$H$304,IFERROR(SMALL(IF(('Daily Ledger'!$B$5:$B$304="INCOME")*('Daily Ledger'!$G$5:$G$304>0),ROW('Daily Ledger'!$B$5:$B$304)-4),10),"")),"")} -> #REF!
A16: {=IFERROR(INDEX('Daily Ledger'!$A$5:$A$304,IFERROR(SMALL(IF(('Daily Ledger'!$B$5:$B$304="INCOME")*('Daily Ledger'!$G$5:$G$304>0),ROW('Daily Ledger'!$B$5:$B$304)-4),11),"")),"")} -> #REF! | B16: {=IFERROR(INDEX('Daily Ledger'!$D$5:$D$304,IFERROR(SMALL(IF(('Daily Ledger'!$B$5:$B$304="INCOME")*('Daily Ledger'!$G$5:$G$304>0),ROW('Daily Ledger'!$B$5:$B$304)-4),11),"")),"")} -> #REF! | C16: {=IFERROR(INDEX('Daily Ledger'!$E$5:$E$304,IFERROR(SMALL(IF(('Daily Ledger'!$B$5:$B$304="INCOME")*('Daily Ledger'!$G$5:$G$304>0),ROW('Daily Ledger'!$B$5:$B$304)-4),11),"")),"")} -> #REF! | D16: {=IFERROR(INDEX('Daily Ledger'!$F$5:$F$304,IFERROR(SMALL(IF(('Daily Ledger'!$B$5:$B$304="INCOME")*('Daily Ledger'!$G$5:$G$304>0),ROW('Daily Ledger'!$B$5:$B$304)-4),11),"")),"")} -> #REF! | E16: {=IFERROR(INDEX('Daily Ledger'!$G$5:$G$304,IFERROR(SMALL(IF(('Daily Ledger'!$B$5:$B$304="INCOME")*('Daily Ledger'!$G$5:$G$304>0),ROW('Daily Ledger'!$B$5:$B$304)-4),11),"")),"")} -> #REF! | F16: {=IFERROR(INDEX('Daily Ledger'!$H$5:$H$304,IFERROR(SMALL(IF(('Daily Ledger'!$B$5:$B$304="INCOME")*('Daily Ledger'!$G$5:$G$304>0),ROW('Daily Ledger'!$B$5:$B$304)-4),11),"")),"")} -> #REF!
A17: {=IFERROR(INDEX('Daily Ledger'!$A$5:$A$304,IFERROR(SMALL(IF(('Daily Ledger'!$B$5:$B$304="INCOME")*('Daily Ledger'!$G$5:$G$304>0),ROW('Daily Ledger'!$B$5:$B$304)-4),12),"")),"")} -> #REF! | B17: {=IFERROR(INDEX('Daily Ledger'!$D$5:$D$304,IFERROR(SMALL(IF(('Daily Ledger'!$B$5:$B$304="INCOME")*('Daily Ledger'!$G$5:$G$304>0),ROW('Daily Ledger'!$B$5:$B$304)-4),12),"")),"")} -> #REF! | C17: {=IFERROR(INDEX('Daily Ledger'!$E$5:$E$304,IFERROR(SMALL(IF(('Daily Ledger'!$B$5:$B$304="INCOME")*('Daily Ledger'!$G$5:$G$304>0),ROW('Daily Ledger'!$B$5:$B$304)-4),12),"")),"")} -> #REF! | D17: {=IFERROR(INDEX('Daily Ledger'!$F$5:$F$304,IFERROR(SMALL(IF(('Daily Ledger'!$B$5:$B$304="INCOME")*('Daily Ledger'!$G$5:$G$304>0),ROW('Daily Ledger'!$B$5:$B$304)-4),12),"")),"")} -> #REF! | E17: {=IFERROR(INDEX('Daily Ledger'!$G$5:$G$304,IFERROR(SMALL(IF(('Daily Ledger'!$B$5:$B$304="INCOME")*('Daily Ledger'!$G$5:$G$304>0),ROW('Daily Ledger'!$B$5:$B$304)-4),12),"")),"")} -> #REF! | F17: {=IFERROR(INDEX('Daily Ledger'!$H$5:$H$304,IFERROR(SMALL(IF(('Daily Ledger'!$B$5:$B$304="INCOME")*('Daily Ledger'!$G$5:$G$304>0),ROW('Daily Ledger'!$B$5:$B$304)-4),12),"")),"")} -> #REF!
A18: {=IFERROR(INDEX('Daily Ledger'!$A$5:$A$304,IFERROR(SMALL(IF(('Daily Ledger'!$B$5:$B$304="INCOME")*('Daily Ledger'!$G$5:$G$304>0),ROW('Daily Ledger'!$B$5:$B$304)-4),13),"")),"")} -> #REF! | B18: {=IFERROR(INDEX('Daily Ledger'!$D$5:$D$304,IFERROR(SMALL(IF(('Daily Ledger'!$B$5:$B$304="INCOME")*('Daily Ledger'!$G$5:$G$304>0),ROW('Daily Ledger'!$B$5:$B$304)-4),13),"")),"")} -> #REF! | C18: {=IFERROR(INDEX('Daily Ledger'!$E$5:$E$304,IFERROR(SMALL(IF(('Daily Ledger'!$B$5:$B$304="INCOME")*('Daily Ledger'!$G$5:$G$304>0),ROW('Daily Ledger'!$B$5:$B$304)-4),13),"")),"")} -> #REF! | D18: {=IFERROR(INDEX('Daily Ledger'!$F$5:$F$304,IFERROR(SMALL(IF(('Daily Ledger'!$B$5:$B$304="INCOME")*('Daily Ledger'!$G$5:$G$304>0),ROW('Daily Ledger'!$B$5:$B$304)-4),13),"")),"")} -> #REF! | E18: {=IFERROR(INDEX('Daily Ledger'!$G$5:$G$304,IFERROR(SMALL(IF(('Daily Ledger'!$B$5:$B$304="INCOME")*('Daily Ledger'!$G$5:$G$304>0),ROW('Daily Ledger'!$B$5:$B$304)-4),13),"")),"")} -> #REF! | F18: {=IFERROR(INDEX('Daily Ledger'!$H$5:$H$304,IFERROR(SMALL(IF(('Daily Ledger'!$B$5:$B$304="INCOME")*('Daily Ledger'!$G$5:$G$304>0),ROW('Daily Ledger'!$B$5:$B$304)-4),13),"")),"")} -> #REF!
A19: {=IFERROR(INDEX('Daily Ledger'!$A$5:$A$304,IFERROR(SMALL(IF(('Daily Ledger'!$B$5:$B$304="INCOME")*('Daily Ledger'!$G$5:$G$304>0),ROW('Daily Ledger'!$B$5:$B$304)-4),14),"")),"")} -> #REF! | B19: {=IFERROR(INDEX('Daily Ledger'!$D$5:$D$304,IFERROR(SMALL(IF(('Daily Ledger'!$B$5:$B$304="INCOME")*('Daily Ledger'!$G$5:$G$304>0),ROW('Daily Ledger'!$B$5:$B$304)-4),14),"")),"")} -> #REF! | C19: {=IFERROR(INDEX('Daily Ledger'!$E$5:$E$304,IFERROR(SMALL(IF(('Daily Ledger'!$B$5:$B$304="INCOME")*('Daily Ledger'!$G$5:$G$304>0),ROW('Daily Ledger'!$B$5:$B$304)-4),14),"")),"")} -> #REF! | D19: {=IFERROR(INDEX('Daily Ledger'!$F$5:$F$304,IFERROR(SMALL(IF(('Daily Ledger'!$B$5:$B$304="INCOME")*('Daily Ledger'!$G$5:$G$304>0),ROW('Daily Ledger'!$B$5:$B$304)-4),14),"")),"")} -> #REF! | E19: {=IFERROR(INDEX('Daily Ledger'!$G$5:$G$304,IFERROR(SMALL(IF(('Daily Ledger'!$B$5:$B$304="INCOME")*('Daily Ledger'!$G$5:$G$304>0),ROW('Daily Ledger'!$B$5:$B$304)-4),14),"")),"")} -> #REF! | F19: {=IFERROR(INDEX('Daily Ledger'!$H$5:$H$304,IFERROR(SMALL(IF(('Daily Ledger'!$B$5:$B$304="INCOME")*('Daily Ledger'!$G$5:$G$304>0),ROW('Daily Ledger'!$B$5:$B$304)-4),14),"")),"")} -> #REF!
A20: {=IFERROR(INDEX('Daily Ledger'!$A$5:$A$304,IFERROR(SMALL(IF(('Daily Ledger'!$B$5:$B$304="INCOME")*('Daily Ledger'!$G$5:$G$304>0),ROW('Daily Ledger'!$B$5:$B$304)-4),15),"")),"")} -> #REF! | B20: {=IFERROR(INDEX('Daily Ledger'!$D$5:$D$304,IFERROR(SMALL(IF(('Daily Ledger'!$B$5:$B$304="INCOME")*('Daily Ledger'!$G$5:$G$304>0),ROW('Daily Ledger'!$B$5:$B$304)-4),15),"")),"")} -> #REF! | C20: {=IFERROR(INDEX('Daily Ledger'!$E$5:$E$304,IFERROR(SMALL(IF(('Daily Ledger'!$B$5:$B$304="INCOME")*('Daily Ledger'!$G$5:$G$304>0),ROW('Daily Ledger'!$B$5:$B$304)-4),15),"")),"")} -> #REF! | D20: {=IFERROR(INDEX('Daily Ledger'!$F$5:$F$304,IFERROR(SMALL(IF(('Daily Ledger'!$B$5:$B$304="INCOME")*('Daily Ledger'!$G$5:$G$304>0),ROW('Daily Ledger'!$B$5:$B$304)-4),15),"")),"")} -> #REF! | E20: {=IFERROR(INDEX('Daily Ledger'!$G$5:$G$304,IFERROR(SMALL(IF(('Daily Ledger'!$B$5:$B$304="INCOME")*('Daily Ledger'!$G$5:$G$304>0),ROW('Daily Ledger'!$B$5:$B$304)-4),15),"")),"")} -> #REF! | F20: {=IFERROR(INDEX('Daily Ledger'!$H$5:$H$304,IFERROR(SMALL(IF(('Daily Ledger'!$B$5:$B$304="INCOME")*('Daily Ledger'!$G$5:$G$304>0),ROW('Daily Ledger'!$B$5:$B$304)-4),15),"")),"")} -> #REF!
A21: {=IFERROR(INDEX('Daily Ledger'!$A$5:$A$304,IFERROR(SMALL(IF(('Daily Ledger'!$B$5:$B$304="INCOME")*('Daily Ledger'!$G$5:$G$304>0),ROW('Daily Ledger'!$B$5:$B$304)-4),16),"")),"")} -> #REF! | B21: {=IFERROR(INDEX('Daily Ledger'!$D$5:$D$304,IFERROR(SMALL(IF(('Daily Ledger'!$B$5:$B$304="INCOME")*('Daily Ledger'!$G$5:$G$304>0),ROW('Daily Ledger'!$B$5:$B$304)-4),16),"")),"")} -> #REF! | C21: {=IFERROR(INDEX('Daily Ledger'!$E$5:$E$304,IFERROR(SMALL(IF(('Daily Ledger'!$B$5:$B$304="INCOME")*('Daily Ledger'!$G$5:$G$304>0),ROW('Daily Ledger'!$B$5:$B$304)-4),16),"")),"")} -> #REF! | D21: {=IFERROR(INDEX('Daily Ledger'!$F$5:$F$304,IFERROR(SMALL(IF(('Daily Ledger'!$B$5:$B$304="INCOME")*('Daily Ledger'!$G$5:$G$304>0),ROW('Daily Ledger'!$B$5:$B$304)-4),16),"")),"")} -> #REF! | E21: {=IFERROR(INDEX('Daily Ledger'!$G$5:$G$304,IFERROR(SMALL(IF(('Daily Ledger'!$B$5:$B$304="INCOME")*('Daily Ledger'!$G$5:$G$304>0),ROW('Daily Ledger'!$B$5:$B$304)-4),16),"")),"")} -> #REF! | F21: {=IFERROR(INDEX('Daily Ledger'!$H$5:$H$304,IFERROR(SMALL(IF(('Daily Ledger'!$B$5:$B$304="INCOME")*('Daily Ledger'!$G$5:$G$304>0),ROW('Daily Ledger'!$B$5:$B$304)-4),16),"")),"")} -> #REF!
A22: {=IFERROR(INDEX('Daily Ledger'!$A$5:$A$304,IFERROR(SMALL(IF(('Daily Ledger'!$B$5:$B$304="INCOME")*('Daily Ledger'!$G$5:$G$304>0),ROW('Daily Ledger'!$B$5:$B$304)-4),17),"")),"")} -> #REF! | B22: {=IFERROR(INDEX('Daily Ledger'!$D$5:$D$304,IFERROR(SMALL(IF(('Daily Ledger'!$B$5:$B$304="INCOME")*('Daily Ledger'!$G$5:$G$304>0),ROW('Daily Ledger'!$B$5:$B$304)-4),17),"")),"")} -> #REF! | C22: {=IFERROR(INDEX('Daily Ledger'!$E$5:$E$304,IFERROR(SMALL(IF(('Daily Ledger'!$B$5:$B$304="INCOME")*('Daily Ledger'!$G$5:$G$304>0),ROW('Daily Ledger'!$B$5:$B$304)-4),17),"")),"")} -> #REF! | D22: {=IFERROR(INDEX('Daily Ledger'!$F$5:$F$304,IFERROR(SMALL(IF(('Daily Ledger'!$B$5:$B$304="INCOME")*('Daily Ledger'!$G$5:$G$304>0),ROW('Daily Ledger'!$B$5:$B$304)-4),17),"")),"")} -> #REF! | E22: {=IFERROR(INDEX('Daily Ledger'!$G$5:$G$304,IFERROR(SMALL(IF(('Daily Ledger'!$B$5:$B$304="INCOME")*('Daily Ledger'!$G$5:$G$304>0),ROW('Daily Ledger'!$B$5:$B$304)-4),17),"")),"")} -> #REF! | F22: {=IFERROR(INDEX('Daily Ledger'!$H$5:$H$304,IFERROR(SMALL(IF(('Daily Ledger'!$B$5:$B$304="INCOME")*('Daily Ledger'!$G$5:$G$304>0),ROW('Daily Ledger'!$B$5:$B$304)-4),17),"")),"")} -> #REF!
A23: {=IFERROR(INDEX('Daily Ledger'!$A$5:$A$304,IFERROR(SMALL(IF(('Daily Ledger'!$B$5:$B$304="INCOME")*('Daily Ledger'!$G$5:$G$304>0),ROW('Daily Ledger'!$B$5:$B$304)-4),18),"")),"")} -> #REF! | B23: {=IFERROR(INDEX('Daily Ledger'!$D$5:$D$304,IFERROR(SMALL(IF(('Daily Ledger'!$B$5:$B$304="INCOME")*('Daily Ledger'!$G$5:$G$304>0),ROW('Daily Ledger'!$B$5:$B$304)-4),18),"")),"")} -> #REF! | C23: {=IFERROR(INDEX('Daily Ledger'!$E$5:$E$304,IFERROR(SMALL(IF(('Daily Ledger'!$B$5:$B$304="INCOME")*('Daily Ledger'!$G$5:$G$304>0),ROW('Daily Ledger'!$B$5:$B$304)-4),18),"")),"")} -> #REF! | D23: {=IFERROR(INDEX('Daily Ledger'!$F$5:$F$304,IFERROR(SMALL(IF(('Daily Ledger'!$B$5:$B$304="INCOME")*('Daily Ledger'!$G$5:$G$304>0),ROW('Daily Ledger'!$B$5:$B$304)-4),18),"")),"")} -> #REF! | E23: {=IFERROR(INDEX('Daily Ledger'!$G$5:$G$304,IFERROR(SMALL(IF(('Daily Ledger'!$B$5:$B$304="INCOME")*('Daily Ledger'!$G$5:$G$304>0),ROW('Daily Ledger'!$B$5:$B$304)-4),18),"")),"")} -> #REF! | F23: {=IFERROR(INDEX('Daily Ledger'!$H$5:$H$304,IFERROR(SMALL(IF(('Daily Ledger'!$B$5:$B$304="INCOME")*('Daily Ledger'!$G$5:$G$304>0),ROW('Daily Ledger'!$B$5:$B$304)-4),18),"")),"")} -> #REF!
A24: {=IFERROR(INDEX('Daily Ledger'!$A$5:$A$304,IFERROR(SMALL(IF(('Daily Ledger'!$B$5:$B$304="INCOME")*('Daily Ledger'!$G$5:$G$304>0),ROW('Daily Ledger'!$B$5:$B$304)-4),19),"")),"")} -> #REF! | B24: {=IFERROR(INDEX('Daily Ledger'!$D$5:$D$304,IFERROR(SMALL(IF(('Daily Ledger'!$B$5:$B$304="INCOME")*('Daily Ledger'!$G$5:$G$304>0),ROW('Daily Ledger'!$B$5:$B$304)-4),19),"")),"")} -> #REF! | C24: {=IFERROR(INDEX('Daily Ledger'!$E$5:$E$304,IFERROR(SMALL(IF(('Daily Ledger'!$B$5:$B$304="INCOME")*('Daily Ledger'!$G$5:$G$304>0),ROW('Daily Ledger'!$B$5:$B$304)-4),19),"")),"")} -> #REF! | D24: {=IFERROR(INDEX('Daily Ledger'!$F$5:$F$304,IFERROR(SMALL(IF(('Daily Ledger'!$B$5:$B$304="INCOME")*('Daily Ledger'!$G$5:$G$304>0),ROW('Daily Ledger'!$B$5:$B$304)-4),19),"")),"")} -> #REF! | E24: {=IFERROR(INDEX('Daily Ledger'!$G$5:$G$304,IFERROR(SMALL(IF(('Daily Ledger'!$B$5:$B$304="INCOME")*('Daily Ledger'!$G$5:$G$304>0),ROW('Daily Ledger'!$B$5:$B$304)-4),19),"")),"")} -> #REF! | F24: {=IFERROR(INDEX('Daily Ledger'!$H$5:$H$304,IFERROR(SMALL(IF(('Daily Ledger'!$B$5:$B$304="INCOME")*('Daily Ledger'!$G$5:$G$304>0),ROW('Daily Ledger'!$B$5:$B$304)-4),19),"")),"")} -> #REF!
A25: {=IFERROR(INDEX('Daily Ledger'!$A$5:$A$304,IFERROR(SMALL(IF(('Daily Ledger'!$B$5:$B$304="INCOME")*('Daily Ledger'!$G$5:$G$304>0),ROW('Daily Ledger'!$B$5:$B$304)-4),20),"")),"")} -> #REF! | B25: {=IFERROR(INDEX('Daily Ledger'!$D$5:$D$304,IFERROR(SMALL(IF(('Daily Ledger'!$B$5:$B$304="INCOME")*('Daily Ledger'!$G$5:$G$304>0),ROW('Daily Ledger'!$B$5:$B$304)-4),20),"")),"")} -> #REF! | C25: {=IFERROR(INDEX('Daily Ledger'!$E$5:$E$304,IFERROR(SMALL(IF(('Daily Ledger'!$B$5:$B$304="INCOME")*('Daily Ledger'!$G$5:$G$304>0),ROW('Daily Ledger'!$B$5:$B$304)-4),20),"")),"")} -> #REF! | D25: {=IFERROR(INDEX('Daily Ledger'!$F$5:$F$304,IFERROR(SMALL(IF(('Daily Ledger'!$B$5:$B$304="INCOME")*('Daily Ledger'!$G$5:$G$304>0),ROW('Daily Ledger'!$B$5:$B$304)-4),20),"")),"")} -> #REF! | E25: {=IFERROR(INDEX('Daily Ledger'!$G$5:$G$304,IFERROR(SMALL(IF(('Daily Ledger'!$B$5:$B$304="INCOME")*('Daily Ledger'!$G$5:$G$304>0),ROW('Daily Ledger'!$B$5:$B$304)-4),20),"")),"")} -> #REF! | F25: {=IFERROR(INDEX('Daily Ledger'!$H$5:$H$304,IFERROR(SMALL(IF(('Daily Ledger'!$B$5:$B$304="INCOME")*('Daily Ledger'!$G$5:$G$304>0),ROW('Daily Ledger'!$B$5:$B$304)-4),20),"")),"")} -> #REF!
A26: {=IFERROR(INDEX('Daily Ledger'!$A$5:$A$304,IFERROR(SMALL(IF(('Daily Ledger'!$B$5:$B$304="INCOME")*('Daily Ledger'!$G$5:$G$304>0),ROW('Daily Ledger'!$B$5:$B$304)-4),21),"")),"")} -> #REF! | B26: {=IFERROR(INDEX('Daily Ledger'!$D$5:$D$304,IFERROR(SMALL(IF(('Daily Ledger'!$B$5:$B$304="INCOME")*('Daily Ledger'!$G$5:$G$304>0),ROW('Daily Ledger'!$B$5:$B$304)-4),21),"")),"")} -> #REF! | C26: {=IFERROR(INDEX('Daily Ledger'!$E$5:$E$304,IFERROR(SMALL(IF(('Daily Ledger'!$B$5:$B$304="INCOME")*('Daily Ledger'!$G$5:$G$304>0),ROW('Daily Ledger'!$B$5:$B$304)-4),21),"")),"")} -> #REF! | D26: {=IFERROR(INDEX('Daily Ledger'!$F$5:$F$304,IFERROR(SMALL(IF(('Daily Ledger'!$B$5:$B$304="INCOME")*('Daily Ledger'!$G$5:$G$304>0),ROW('Daily Ledger'!$B$5:$B$304)-4),21),"")),"")} -> #REF! | E26: {=IFERROR(INDEX('Daily Ledger'!$G$5:$G$304,IFERROR(SMALL(IF(('Daily Ledger'!$B$5:$B$304="INCOME")*('Daily Ledger'!$G$5:$G$304>0),ROW('Daily Ledger'!$B$5:$B$304)-4),21),"")),"")} -> #REF! | F26: {=IFERROR(INDEX('Daily Ledger'!$H$5:$H$304,IFERROR(SMALL(IF(('Daily Ledger'!$B$5:$B$304="INCOME")*('Daily Ledger'!$G$5:$G$304>0),ROW('Daily Ledger'!$B$5:$B$304)-4),21),"")),"")} -> #REF!
A27: {=IFERROR(INDEX('Daily Ledger'!$A$5:$A$304,IFERROR(SMALL(IF(('Daily Ledger'!$B$5:$B$304="INCOME")*('Daily Ledger'!$G$5:$G$304>0),ROW('Daily Ledger'!$B$5:$B$304)-4),22),"")),"")} -> #REF! | B27: {=IFERROR(INDEX('Daily Ledger'!$D$5:$D$304,IFERROR(SMALL(IF(('Daily Ledger'!$B$5:$B$304="INCOME")*('Daily Ledger'!$G$5:$G$304>0),ROW('Daily Ledger'!$B$5:$B$304)-4),22),"")),"")} -> #REF! | C27: {=IFERROR(INDEX('Daily Ledger'!$E$5:$E$304,IFERROR(SMALL(IF(('Daily Ledger'!$B$5:$B$304="INCOME")*('Daily Ledger'!$G$5:$G$304>0),ROW('Daily Ledger'!$B$5:$B$304)-4),22),"")),"")} -> #REF! | D27: {=IFERROR(INDEX('Daily Ledger'!$F$5:$F$304,IFERROR(SMALL(IF(('Daily Ledger'!$B$5:$B$304="INCOME")*('Daily Ledger'!$G$5:$G$304>0),ROW('Daily Ledger'!$B$5:$B$304)-4),22),"")),"")} -> #REF! | E27: {=IFERROR(INDEX('Daily Ledger'!$G$5:$G$304,IFERROR(SMALL(IF(('Daily Ledger'!$B$5:$B$304="INCOME")*('Daily Ledger'!$G$5:$G$304>0),ROW('Daily Ledger'!$B$5:$B$304)-4),22),"")),"")} -> #REF! | F27: {=IFERROR(INDEX('Daily Ledger'!$H$5:$H$304,IFERROR(SMALL(IF(('Daily Ledger'!$B$5:$B$304="INCOME")*('Daily Ledger'!$G$5:$G$304>0),ROW('Daily Ledger'!$B$5:$B$304)-4),22),"")),"")} -> #REF!
A28: {=IFERROR(INDEX('Daily Ledger'!$A$5:$A$304,IFERROR(SMALL(IF(('Daily Ledger'!$B$5:$B$304="INCOME")*('Daily Ledger'!$G$5:$G$304>0),ROW('Daily Ledger'!$B$5:$B$304)-4),23),"")),"")} -> #REF! | B28: {=IFERROR(INDEX('Daily Ledger'!$D$5:$D$304,IFERROR(SMALL(IF(('Daily Ledger'!$B$5:$B$304="INCOME")*('Daily Ledger'!$G$5:$G$304>0),ROW('Daily Ledger'!$B$5:$B$304)-4),23),"")),"")} -> #REF! | C28: {=IFERROR(INDEX('Daily Ledger'!$E$5:$E$304,IFERROR(SMALL(IF(('Daily Ledger'!$B$5:$B$304="INCOME")*('Daily Ledger'!$G$5:$G$304>0),ROW('Daily Ledger'!$B$5:$B$304)-4),23),"")),"")} -> #REF! | D28: {=IFERROR(INDEX('Daily Ledger'!$F$5:$F$304,IFERROR(SMALL(IF(('Daily Ledger'!$B$5:$B$304="INCOME")*('Daily Ledger'!$G$5:$G$304>0),ROW('Daily Ledger'!$B$5:$B$304)-4),23),"")),"")} -> #REF! | E28: {=IFERROR(INDEX('Daily Ledger'!$G$5:$G$304,IFERROR(SMALL(IF(('Daily Ledger'!$B$5:$B$304="INCOME")*('Daily Ledger'!$G$5:$G$304>0),ROW('Daily Ledger'!$B$5:$B$304)-4),23),"")),"")} -> #REF! | F28: {=IFERROR(INDEX('Daily Ledger'!$H$5:$H$304,IFERROR(SMALL(IF(('Daily Ledger'!$B$5:$B$304="INCOME")*('Daily Ledger'!$G$5:$G$304>0),ROW('Daily Ledger'!$B$5:$B$304)-4),23),"")),"")} -> #REF!
A29: {=IFERROR(INDEX('Daily Ledger'!$A$5:$A$304,IFERROR(SMALL(IF(('Daily Ledger'!$B$5:$B$304="INCOME")*('Daily Ledger'!$G$5:$G$304>0),ROW('Daily Ledger'!$B$5:$B$304)-4),24),"")),"")} -> #REF! | B29: {=IFERROR(INDEX('Daily Ledger'!$D$5:$D$304,IFERROR(SMALL(IF(('Daily Ledger'!$B$5:$B$304="INCOME")*('Daily Ledger'!$G$5:$G$304>0),ROW('Daily Ledger'!$B$5:$B$304)-4),24),"")),"")} -> #REF! | C29: {=IFERROR(INDEX('Daily Ledger'!$E$5:$E$304,IFERROR(SMALL(IF(('Daily Ledger'!$B$5:$B$304="INCOME")*('Daily Ledger'!$G$5:$G$304>0),ROW('Daily Ledger'!$B$5:$B$304)-4),24),"")),"")} -> #REF! | D29: {=IFERROR(INDEX('Daily Ledger'!$F$5:$F$304,IFERROR(SMALL(IF(('Daily Ledger'!$B$5:$B$304="INCOME")*('Daily Ledger'!$G$5:$G$304>0),ROW('Daily Ledger'!$B$5:$B$304)-4),24),"")),"")} -> #REF! | E29: {=IFERROR(INDEX('Daily Ledger'!$G$5:$G$304,IFERROR(SMALL(IF(('Daily Ledger'!$B$5:$B$304="INCOME")*('Daily Ledger'!$G$5:$G$304>0),ROW('Daily Ledger'!$B$5:$B$304)-4),24),"")),"")} -> #REF! | F29: {=IFERROR(INDEX('Daily Ledger'!$H$5:$H$304,IFERROR(SMALL(IF(('Daily Ledger'!$B$5:$B$304="INCOME")*('Daily Ledger'!$G$5:$G$304>0),ROW('Daily Ledger'!$B$5:$B$304)-4),24),"")),"")} -> #REF!
A30: {=IFERROR(INDEX('Daily Ledger'!$A$5:$A$304,IFERROR(SMALL(IF(('Daily Ledger'!$B$5:$B$304="INCOME")*('Daily Ledger'!$G$5:$G$304>0),ROW('Daily Ledger'!$B$5:$B$304)-4),25),"")),"")} -> #REF! | B30: {=IFERROR(INDEX('Daily Ledger'!$D$5:$D$304,IFERROR(SMALL(IF(('Daily Ledger'!$B$5:$B$304="INCOME")*('Daily Ledger'!$G$5:$G$304>0),ROW('Daily Ledger'!$B$5:$B$304)-4),25),"")),"")} -> #REF! | C30: {=IFERROR(INDEX('Daily Ledger'!$E$5:$E$304,IFERROR(SMALL(IF(('Daily Ledger'!$B$5:$B$304="INCOME")*('Daily Ledger'!$G$5:$G$304>0),ROW('Daily Ledger'!$B$5:$B$304)-4),25),"")),"")} -> #REF! | D30: {=IFERROR(INDEX('Daily Ledger'!$F$5:$F$304,IFERROR(SMALL(IF(('Daily Ledger'!$B$5:$B$304="INCOME")*('Daily Ledger'!$G$5:$G$304>0),ROW('Daily Ledger'!$B$5:$B$304)-4),25),"")),"")} -> #REF! | E30: {=IFERROR(INDEX('Daily Ledger'!$G$5:$G$304,IFERROR(SMALL(IF(('Daily Ledger'!$B$5:$B$304="INCOME")*('Daily Ledger'!$G$5:$G$304>0),ROW('Daily Ledger'!$B$5:$B$304)-4),25),"")),"")} -> #REF! | F30: {=IFERROR(INDEX('Daily Ledger'!$H$5:$H$304,IFERROR(SMALL(IF(('Daily Ledger'!$B$5:$B$304="INCOME")*('Daily Ledger'!$G$5:$G$304>0),ROW('Daily Ledger'!$B$5:$B$304)-4),25),"")),"")} -> #REF!
A31: {=IFERROR(INDEX('Daily Ledger'!$A$5:$A$304,IFERROR(SMALL(IF(('Daily Ledger'!$B$5:$B$304="INCOME")*('Daily Ledger'!$G$5:$G$304>0),ROW('Daily Ledger'!$B$5:$B$304)-4),26),"")),"")} -> #REF! | B31: {=IFERROR(INDEX('Daily Ledger'!$D$5:$D$304,IFERROR(SMALL(IF(('Daily Ledger'!$B$5:$B$304="INCOME")*('Daily Ledger'!$G$5:$G$304>0),ROW('Daily Ledger'!$B$5:$B$304)-4),26),"")),"")} -> #REF! | C31: {=IFERROR(INDEX('Daily Ledger'!$E$5:$E$304,IFERROR(SMALL(IF(('Daily Ledger'!$B$5:$B$304="INCOME")*('Daily Ledger'!$G$5:$G$304>0),ROW('Daily Ledger'!$B$5:$B$304)-4),26),"")),"")} -> #REF! | D31: {=IFERROR(INDEX('Daily Ledger'!$F$5:$F$304,IFERROR(SMALL(IF(('Daily Ledger'!$B$5:$B$304="INCOME")*('Daily Ledger'!$G$5:$G$304>0),ROW('Daily Ledger'!$B$5:$B$304)-4),26),"")),"")} -> #REF! | E31: {=IFERROR(INDEX('Daily Ledger'!$G$5:$G$304,IFERROR(SMALL(IF(('Daily Ledger'!$B$5:$B$304="INCOME")*('Daily Ledger'!$G$5:$G$304>0),ROW('Daily Ledger'!$B$5:$B$304)-4),26),"")),"")} -> #REF! | F31: {=IFERROR(INDEX('Daily Ledger'!$H$5:$H$304,IFERROR(SMALL(IF(('Daily Ledger'!$B$5:$B$304="INCOME")*('Daily Ledger'!$G$5:$G$304>0),ROW('Daily Ledger'!$B$5:$B$304)-4),26),"")),"")} -> #REF!
A32: {=IFERROR(INDEX('Daily Ledger'!$A$5:$A$304,IFERROR(SMALL(IF(('Daily Ledger'!$B$5:$B$304="INCOME")*('Daily Ledger'!$G$5:$G$304>0),ROW('Daily Ledger'!$B$5:$B$304)-4),27),"")),"")} -> #REF! | B32: {=IFERROR(INDEX('Daily Ledger'!$D$5:$D$304,IFERROR(SMALL(IF(('Daily Ledger'!$B$5:$B$304="INCOME")*('Daily Ledger'!$G$5:$G$304>0),ROW('Daily Ledger'!$B$5:$B$304)-4),27),"")),"")} -> #REF! | C32: {=IFERROR(INDEX('Daily Ledger'!$E$5:$E$304,IFERROR(SMALL(IF(('Daily Ledger'!$B$5:$B$304="INCOME")*('Daily Ledger'!$G$5:$G$304>0),ROW('Daily Ledger'!$B$5:$B$304)-4),27),"")),"")} -> #REF! | D32: {=IFERROR(INDEX('Daily Ledger'!$F$5:$F$304,IFERROR(SMALL(IF(('Daily Ledger'!$B$5:$B$304="INCOME")*('Daily Ledger'!$G$5:$G$304>0),ROW('Daily Ledger'!$B$5:$B$304)-4),27),"")),"")} -> #REF! | E32: {=IFERROR(INDEX('Daily Ledger'!$G$5:$G$304,IFERROR(SMALL(IF(('Daily Ledger'!$B$5:$B$304="INCOME")*('Daily Ledger'!$G$5:$G$304>0),ROW('Daily Ledger'!$B$5:$B$304)-4),27),"")),"")} -> #REF! | F32: {=IFERROR(INDEX('Daily Ledger'!$H$5:$H$304,IFERROR(SMALL(IF(('Daily Ledger'!$B$5:$B$304="INCOME")*('Daily Ledger'!$G$5:$G$304>0),ROW('Daily Ledger'!$B$5:$B$304)-4),27),"")),"")} -> #REF!
A33: {=IFERROR(INDEX('Daily Ledger'!$A$5:$A$304,IFERROR(SMALL(IF(('Daily Ledger'!$B$5:$B$304="INCOME")*('Daily Ledger'!$G$5:$G$304>0),ROW('Daily Ledger'!$B$5:$B$304)-4),28),"")),"")} -> #REF! | B33: {=IFERROR(INDEX('Daily Ledger'!$D$5:$D$304,IFERROR(SMALL(IF(('Daily Ledger'!$B$5:$B$304="INCOME")*('Daily Ledger'!$G$5:$G$304>0),ROW('Daily Ledger'!$B$5:$B$304)-4),28),"")),"")} -> #REF! | C33: {=IFERROR(INDEX('Daily Ledger'!$E$5:$E$304,IFERROR(SMALL(IF(('Daily Ledger'!$B$5:$B$304="INCOME")*('Daily Ledger'!$G$5:$G$304>0),ROW('Daily Ledger'!$B$5:$B$304)-4),28),"")),"")} -> #REF! | D33: {=IFERROR(INDEX('Daily Ledger'!$F$5:$F$304,IFERROR(SMALL(IF(('Daily Ledger'!$B$5:$B$304="INCOME")*('Daily Ledger'!$G$5:$G$304>0),ROW('Daily Ledger'!$B$5:$B$304)-4),28),"")),"")} -> #REF! | E33: {=IFERROR(INDEX('Daily Ledger'!$G$5:$G$304,IFERROR(SMALL(IF(('Daily Ledger'!$B$5:$B$304="INCOME")*('Daily Ledger'!$G$5:$G$304>0),ROW('Daily Ledger'!$B$5:$B$304)-4),28),"")),"")} -> #REF! | F33: {=IFERROR(INDEX('Daily Ledger'!$H$5:$H$304,IFERROR(SMALL(IF(('Daily Ledger'!$B$5:$B$304="INCOME")*('Daily Ledger'!$G$5:$G$304>0),ROW('Daily Ledger'!$B$5:$B$304)-4),28),"")),"")} -> #REF!
A34: {=IFERROR(INDEX('Daily Ledger'!$A$5:$A$304,IFERROR(SMALL(IF(('Daily Ledger'!$B$5:$B$304="INCOME")*('Daily Ledger'!$G$5:$G$304>0),ROW('Daily Ledger'!$B$5:$B$304)-4),29),"")),"")} -> #REF! | B34: {=IFERROR(INDEX('Daily Ledger'!$D$5:$D$304,IFERROR(SMALL(IF(('Daily Ledger'!$B$5:$B$304="INCOME")*('Daily Ledger'!$G$5:$G$304>0),ROW('Daily Ledger'!$B$5:$B$304)-4),29),"")),"")} -> #REF! | C34: {=IFERROR(INDEX('Daily Ledger'!$E$5:$E$304,IFERROR(SMALL(IF(('Daily Ledger'!$B$5:$B$304="INCOME")*('Daily Ledger'!$G$5:$G$304>0),ROW('Daily Ledger'!$B$5:$B$304)-4),29),"")),"")} -> #REF! | D34: {=IFERROR(INDEX('Daily Ledger'!$F$5:$F$304,IFERROR(SMALL(IF(('Daily Ledger'!$B$5:$B$304="INCOME")*('Daily Ledger'!$G$5:$G$304>0),ROW('Daily Ledger'!$B$5:$B$304)-4),29),"")),"")} -> #REF! | E34: {=IFERROR(INDEX('Daily Ledger'!$G$5:$G$304,IFERROR(SMALL(IF(('Daily Ledger'!$B$5:$B$304="INCOME")*('Daily Ledger'!$G$5:$G$304>0),ROW('Daily Ledger'!$B$5:$B$304)-4),29),"")),"")} -> #REF! | F34: {=IFERROR(INDEX('Daily Ledger'!$H$5:$H$304,IFERROR(SMALL(IF(('Daily Ledger'!$B$5:$B$304="INCOME")*('Daily Ledger'!$G$5:$G$304>0),ROW('Daily Ledger'!$B$5:$B$304)-4),29),"")),"")} -> #REF!
A35: {=IFERROR(INDEX('Daily Ledger'!$A$5:$A$304,IFERROR(SMALL(IF(('Daily Ledger'!$B$5:$B$304="INCOME")*('Daily Ledger'!$G$5:$G$304>0),ROW('Daily Ledger'!$B$5:$B$304)-4),30),"")),"")} -> #REF! | B35: {=IFERROR(INDEX('Daily Ledger'!$D$5:$D$304,IFERROR(SMALL(IF(('Daily Ledger'!$B$5:$B$304="INCOME")*('Daily Ledger'!$G$5:$G$304>0),ROW('Daily Ledger'!$B$5:$B$304)-4),30),"")),"")} -> #REF! | C35: {=IFERROR(INDEX('Daily Ledger'!$E$5:$E$304,IFERROR(SMALL(IF(('Daily Ledger'!$B$5:$B$304="INCOME")*('Daily Ledger'!$G$5:$G$304>0),ROW('Daily Ledger'!$B$5:$B$304)-4),30),"")),"")} -> #REF! | D35: {=IFERROR(INDEX('Daily Ledger'!$F$5:$F$304,IFERROR(SMALL(IF(('Daily Ledger'!$B$5:$B$304="INCOME")*('Daily Ledger'!$G$5:$G$304>0),ROW('Daily Ledger'!$B$5:$B$304)-4),30),"")),"")} -> #REF! | E35: {=IFERROR(INDEX('Daily Ledger'!$G$5:$G$304,IFERROR(SMALL(IF(('Daily Ledger'!$B$5:$B$304="INCOME")*('Daily Ledger'!$G$5:$G$304>0),ROW('Daily Ledger'!$B$5:$B$304)-4),30),"")),"")} -> #REF! | F35: {=IFERROR(INDEX('Daily Ledger'!$H$5:$H$304,IFERROR(SMALL(IF(('Daily Ledger'!$B$5:$B$304="INCOME")*('Daily Ledger'!$G$5:$G$304>0),ROW('Daily Ledger'!$B$5:$B$304)-4),30),"")),"")} -> #REF!
A36: {=IFERROR(INDEX('Daily Ledger'!$A$5:$A$304,IFERROR(SMALL(IF(('Daily Ledger'!$B$5:$B$304="INCOME")*('Daily Ledger'!$G$5:$G$304>0),ROW('Daily Ledger'!$B$5:$B$304)-4),31),"")),"")} -> #REF! | B36: {=IFERROR(INDEX('Daily Ledger'!$D$5:$D$304,IFERROR(SMALL(IF(('Daily Ledger'!$B$5:$B$304="INCOME")*('Daily Ledger'!$G$5:$G$304>0),ROW('Daily Ledger'!$B$5:$B$304)-4),31),"")),"")} -> #REF! | C36: {=IFERROR(INDEX('Daily Ledger'!$E$5:$E$304,IFERROR(SMALL(IF(('Daily Ledger'!$B$5:$B$304="INCOME")*('Daily Ledger'!$G$5:$G$304>0),ROW('Daily Ledger'!$B$5:$B$304)-4),31),"")),"")} -> #REF! | D36: {=IFERROR(INDEX('Daily Ledger'!$F$5:$F$304,IFERROR(SMALL(IF(('Daily Ledger'!$B$5:$B$304="INCOME")*('Daily Ledger'!$G$5:$G$304>0),ROW('Daily Ledger'!$B$5:$B$304)-4),31),"")),"")} -> #REF! | E36: {=IFERROR(INDEX('Daily Ledger'!$G$5:$G$304,IFERROR(SMALL(IF(('Daily Ledger'!$B$5:$B$304="INCOME")*('Daily Ledger'!$G$5:$G$304>0),ROW('Daily Ledger'!$B$5:$B$304)-4),31),"")),"")} -> #REF! | F36: {=IFERROR(INDEX('Daily Ledger'!$H$5:$H$304,IFERROR(SMALL(IF(('Daily Ledger'!$B$5:$B$304="INCOME")*('Daily Ledger'!$G$5:$G$304>0),ROW('Daily Ledger'!$B$5:$B$304)-4),31),"")),"")} -> #REF!
A37: {=IFERROR(INDEX('Daily Ledger'!$A$5:$A$304,IFERROR(SMALL(IF(('Daily Ledger'!$B$5:$B$304="INCOME")*('Daily Ledger'!$G$5:$G$304>0),ROW('Daily Ledger'!$B$5:$B$304)-4),32),"")),"")} -> #REF! | B37: {=IFERROR(INDEX('Daily Ledger'!$D$5:$D$304,IFERROR(SMALL(IF(('Daily Ledger'!$B$5:$B$304="INCOME")*('Daily Ledger'!$G$5:$G$304>0),ROW('Daily Ledger'!$B$5:$B$304)-4),32),"")),"")} -> #REF! | C37: {=IFERROR(INDEX('Daily Ledger'!$E$5:$E$304,IFERROR(SMALL(IF(('Daily Ledger'!$B$5:$B$304="INCOME")*('Daily Ledger'!$G$5:$G$304>0),ROW('Daily Ledger'!$B$5:$B$304)-4),32),"")),"")} -> #REF! | D37: {=IFERROR(INDEX('Daily Ledger'!$F$5:$F$304,IFERROR(SMALL(IF(('Daily Ledger'!$B$5:$B$304="INCOME")*('Daily Ledger'!$G$5:$G$304>0),ROW('Daily Ledger'!$B$5:$B$304)-4),32),"")),"")} -> #REF! | E37: {=IFERROR(INDEX('Daily Ledger'!$G$5:$G$304,IFERROR(SMALL(IF(('Daily Ledger'!$B$5:$B$304="INCOME")*('Daily Ledger'!$G$5:$G$304>0),ROW('Daily Ledger'!$B$5:$B$304)-4),32),"")),"")} -> #REF! | F37: {=IFERROR(INDEX('Daily Ledger'!$H$5:$H$304,IFERROR(SMALL(IF(('Daily Ledger'!$B$5:$B$304="INCOME")*('Daily Ledger'!$G$5:$G$304>0),ROW('Daily Ledger'!$B$5:$B$304)-4),32),"")),"")} -> #REF!
A38: {=IFERROR(INDEX('Daily Ledger'!$A$5:$A$304,IFERROR(SMALL(IF(('Daily Ledger'!$B$5:$B$304="INCOME")*('Daily Ledger'!$G$5:$G$304>0),ROW('Daily Ledger'!$B$5:$B$304)-4),33),"")),"")} -> #REF! | B38: {=IFERROR(INDEX('Daily Ledger'!$D$5:$D$304,IFERROR(SMALL(IF(('Daily Ledger'!$B$5:$B$304="INCOME")*('Daily Ledger'!$G$5:$G$304>0),ROW('Daily Ledger'!$B$5:$B$304)-4),33),"")),"")} -> #REF! | C38: {=IFERROR(INDEX('Daily Ledger'!$E$5:$E$304,IFERROR(SMALL(IF(('Daily Ledger'!$B$5:$B$304="INCOME")*('Daily Ledger'!$G$5:$G$304>0),ROW('Daily Ledger'!$B$5:$B$304)-4),33),"")),"")} -> #REF! | D38: {=IFERROR(INDEX('Daily Ledger'!$F$5:$F$304,IFERROR(SMALL(IF(('Daily Ledger'!$B$5:$B$304="INCOME")*('Daily Ledger'!$G$5:$G$304>0),ROW('Daily Ledger'!$B$5:$B$304)-4),33),"")),"")} -> #REF! | E38: {=IFERROR(INDEX('Daily Ledger'!$G$5:$G$304,IFERROR(SMALL(IF(('Daily Ledger'!$B$5:$B$304="INCOME")*('Daily Ledger'!$G$5:$G$304>0),ROW('Daily Ledger'!$B$5:$B$304)-4),33),"")),"")} -> #REF! | F38: {=IFERROR(INDEX('Daily Ledger'!$H$5:$H$304,IFERROR(SMALL(IF(('Daily Ledger'!$B$5:$B$304="INCOME")*('Daily Ledger'!$G$5:$G$304>0),ROW('Daily Ledger'!$B$5:$B$304)-4),33),"")),"")} -> #REF!
A39: {=IFERROR(INDEX('Daily Ledger'!$A$5:$A$304,IFERROR(SMALL(IF(('Daily Ledger'!$B$5:$B$304="INCOME")*('Daily Ledger'!$G$5:$G$304>0),ROW('Daily Ledger'!$B$5:$B$304)-4),34),"")),"")} -> #REF! | B39: {=IFERROR(INDEX('Daily Ledger'!$D$5:$D$304,IFERROR(SMALL(IF(('Daily Ledger'!$B$5:$B$304="INCOME")*('Daily Ledger'!$G$5:$G$304>0),ROW('Daily Ledger'!$B$5:$B$304)-4),34),"")),"")} -> #REF! | C39: {=IFERROR(INDEX('Daily Ledger'!$E$5:$E$304,IFERROR(SMALL(IF(('Daily Ledger'!$B$5:$B$304="INCOME")*('Daily Ledger'!$G$5:$G$304>0),ROW('Daily Ledger'!$B$5:$B$304)-4),34),"")),"")} -> #REF! | D39: {=IFERROR(INDEX('Daily Ledger'!$F$5:$F$304,IFERROR(SMALL(IF(('Daily Ledger'!$B$5:$B$304="INCOME")*('Daily Ledger'!$G$5:$G$304>0),ROW('Daily Ledger'!$B$5:$B$304)-4),34),"")),"")} -> #REF! | E39: {=IFERROR(INDEX('Daily Ledger'!$G$5:$G$304,IFERROR(SMALL(IF(('Daily Ledger'!$B$5:$B$304="INCOME")*('Daily Ledger'!$G$5:$G$304>0),ROW('Daily Ledger'!$B$5:$B$304)-4),34),"")),"")} -> #REF! | F39: {=IFERROR(INDEX('Daily Ledger'!$H$5:$H$304,IFERROR(SMALL(IF(('Daily Ledger'!$B$5:$B$304="INCOME")*('Daily Ledger'!$G$5:$G$304>0),ROW('Daily Ledger'!$B$5:$B$304)-4),34),"")),"")} -> #REF!
A40: {=IFERROR(INDEX('Daily Ledger'!$A$5:$A$304,IFERROR(SMALL(IF(('Daily Ledger'!$B$5:$B$304="INCOME")*('Daily Ledger'!$G$5:$G$304>0),ROW('Daily Ledger'!$B$5:$B$304)-4),35),"")),"")} -> #REF! | B40: {=IFERROR(INDEX('Daily Ledger'!$D$5:$D$304,IFERROR(SMALL(IF(('Daily Ledger'!$B$5:$B$304="INCOME")*('Daily Ledger'!$G$5:$G$304>0),ROW('Daily Ledger'!$B$5:$B$304)-4),35),"")),"")} -> #REF! | C40: {=IFERROR(INDEX('Daily Ledger'!$E$5:$E$304,IFERROR(SMALL(IF(('Daily Ledger'!$B$5:$B$304="INCOME")*('Daily Ledger'!$G$5:$G$304>0),ROW('Daily Ledger'!$B$5:$B$304)-4),35),"")),"")} -> #REF! | D40: {=IFERROR(INDEX('Daily Ledger'!$F$5:$F$304,IFERROR(SMALL(IF(('Daily Ledger'!$B$5:$B$304="INCOME")*('Daily Ledger'!$G$5:$G$304>0),ROW('Daily Ledger'!$B$5:$B$304)-4),35),"")),"")} -> #REF! | E40: {=IFERROR(INDEX('Daily Ledger'!$G$5:$G$304,IFERROR(SMALL(IF(('Daily Ledger'!$B$5:$B$304="INCOME")*('Daily Ledger'!$G$5:$G$304>0),ROW('Daily Ledger'!$B$5:$B$304)-4),35),"")),"")} -> #REF! | F40: {=IFERROR(INDEX('Daily Ledger'!$H$5:$H$304,IFERROR(SMALL(IF(('Daily Ledger'!$B$5:$B$304="INCOME")*('Daily Ledger'!$G$5:$G$304>0),ROW('Daily Ledger'!$B$5:$B$304)-4),35),"")),"")} -> #REF!
A41: {=IFERROR(INDEX('Daily Ledger'!$A$5:$A$304,IFERROR(SMALL(IF(('Daily Ledger'!$B$5:$B$304="INCOME")*('Daily Ledger'!$G$5:$G$304>0),ROW('Daily Ledger'!$B$5:$B$304)-4),36),"")),"")} -> #REF! | B41: {=IFERROR(INDEX('Daily Ledger'!$D$5:$D$304,IFERROR(SMALL(IF(('Daily Ledger'!$B$5:$B$304="INCOME")*('Daily Ledger'!$G$5:$G$304>0),ROW('Daily Ledger'!$B$5:$B$304)-4),36),"")),"")} -> #REF! | C41: {=IFERROR(INDEX('Daily Ledger'!$E$5:$E$304,IFERROR(SMALL(IF(('Daily Ledger'!$B$5:$B$304="INCOME")*('Daily Ledger'!$G$5:$G$304>0),ROW('Daily Ledger'!$B$5:$B$304)-4),36),"")),"")} -> #REF! | D41: {=IFERROR(INDEX('Daily Ledger'!$F$5:$F$304,IFERROR(SMALL(IF(('Daily Ledger'!$B$5:$B$304="INCOME")*('Daily Ledger'!$G$5:$G$304>0),ROW('Daily Ledger'!$B$5:$B$304)-4),36),"")),"")} -> #REF! | E41: {=IFERROR(INDEX('Daily Ledger'!$G$5:$G$304,IFERROR(SMALL(IF(('Daily Ledger'!$B$5:$B$304="INCOME")*('Daily Ledger'!$G$5:$G$304>0),ROW('Daily Ledger'!$B$5:$B$304)-4),36),"")),"")} -> #REF! | F41: {=IFERROR(INDEX('Daily Ledger'!$H$5:$H$304,IFERROR(SMALL(IF(('Daily Ledger'!$B$5:$B$304="INCOME")*('Daily Ledger'!$G$5:$G$304>0),ROW('Daily Ledger'!$B$5:$B$304)-4),36),"")),"")} -> #REF!
...

Sheet Category Analysis
A1: 🏨 RAYMITON HOTEL — Category Analysis
A2: Based on AMOUNT PAID (actual cash) — updates automatically from Daily Ledger
A4: Category | B4: Total Income (₦) | C4: Total Expenses (₦) | D4: Net Profit (₦) | E4: % of Income | F4: % of Expenses
A5: Rooms | B5: =SUMIFS('Daily Ledger'!F5:F304,'Daily Ledger'!B5:B304,"INCOME",'Daily Ledger'!C5:C304,A5) -> 95000 | C5: =SUMIFS('Daily Ledger'!F5:F304,'Daily Ledger'!B5:B304,"EXPENSE",'Daily Ledger'!C5:C304,A5) -> 0 | D5: =B5-C5 -> 95000 | E5: =IF(B14=0,"-",B5/B14) -> 0.92773438 | F5: =IF(C14=0,"-",C5/C14) -> 0
A6: Bar | B6: =SUMIFS('Daily Ledger'!F5:F304,'Daily Ledger'!B5:B304,"INCOME",'Daily Ledger'!C5:C304,A6) -> 7400 | C6: =SUMIFS('Daily Ledger'!F5:F304,'Daily Ledger'!B5:B304,"EXPENSE",'Daily Ledger'!C5:C304,A6) -> 9700 | D6: =B6-C6 -> -2300 | E6: =IF(B14=0,"-",B6/B14) -> 0.072265625 | F6: =IF(C14=0,"-",C6/C14) -> 0.13333333
A7: Kitchen | B7: =SUMIFS('Daily Ledger'!F5:F304,'Daily Ledger'!B5:B304,"INCOME",'Daily Ledger'!C5:C304,A7) -> 0 | C7: =SUMIFS('Daily Ledger'!F5:F304,'Daily Ledger'!B5:B304,"EXPENSE",'Daily Ledger'!C5:C304,A7) -> 0 | D7: =B7-C7 -> 0 | E7: =IF(B14=0,"-",B7/B14) -> 0 | F7: =IF(C14=0,"-",C7/C14) -> 0
A8: Utilities | B8: =SUMIFS('Daily Ledger'!F5:F304,'Daily Ledger'!B5:B304,"INCOME",'Daily Ledger'!C5:C304,A8) -> 0 | C8: =SUMIFS('Daily Ledger'!F5:F304,'Daily Ledger'!B5:B304,"EXPENSE",'Daily Ledger'!C5:C304,A8) -> 58300 | D8: =B8-C8 -> -58300 | E8: =IF(B14=0,"-",B8/B14) -> 0 | F8: =IF(C14=0,"-",C8/C14) -> 0.80137457
A9: Maintenance | B9: =SUMIFS('Daily Ledger'!F5:F304,'Daily Ledger'!B5:B304,"INCOME",'Daily Ledger'!C5:C304,A9) -> 0 | C9: =SUMIFS('Daily Ledger'!F5:F304,'Daily Ledger'!B5:B304,"EXPENSE",'Daily Ledger'!C5:C304,A9) -> 0 | D9: =B9-C9 -> 0 | E9: =IF(B14=0,"-",B9/B14) -> 0 | F9: =IF(C14=0,"-",C9/C14) -> 0
A10: Salaries | B10: =SUMIFS('Daily Ledger'!F5:F304,'Daily Ledger'!B5:B304,"INCOME",'Daily Ledger'!C5:C304,A10) -> 0 | C10: =SUMIFS('Daily Ledger'!F5:F304,'Daily Ledger'!B5:B304,"EXPENSE",'Daily Ledger'!C5:C304,A10) -> 3500 | D10: =B10-C10 -> -3500 | E10: =IF(B14=0,"-",B10/B14) -> 0 | F10: =IF(C14=0,"-",C10/C14) -> 0.048109966
A11: Supplies | B11: =SUMIFS('Daily Ledger'!F5:F304,'Daily Ledger'!B5:B304,"INCOME",'Daily Ledger'!C5:C304,A11) -> 0 | C11: =SUMIFS('Daily Ledger'!F5:F304,'Daily Ledger'!B5:B304,"EXPENSE",'Daily Ledger'!C5:C304,A11) -> 1250 | D11: =B11-C11 -> -1250 | E11: =IF(B14=0,"-",B11/B14) -> 0 | F11: =IF(C14=0,"-",C11/C14) -> 0.017182131
A12: Other | B12: =SUMIFS('Daily Ledger'!F5:F304,'Daily Ledger'!B5:B304,"INCOME",'Daily Ledger'!C5:C304,A12) -> 0 | C12: =SUMIFS('Daily Ledger'!F5:F304,'Daily Ledger'!B5:B304,"EXPENSE",'Daily Ledger'!C5:C304,A12) -> 0 | D12: =B12-C12 -> 0 | E12: =IF(B14=0,"-",B12/B14) -> 0 | F12: =IF(C14=0,"-",C12/C14) -> 0
A14: GRAND TOTAL | B14: =SUM(B5:B12) -> 102400 | C14: =SUM(C5:C12) -> 72750 | D14: =B14-C14 -> 29650 | E14: "100%" | F14: "100%"

Sheet Category Guide
A1: 📋 Category & Status Guide
A2: ── CATEGORIES ──
A3: Rooms | B3: Lodge payments, room rentals (night/short stay), room-specific items
A4: Bar | B4: Drinks sales, bottles of water/soft drinks/alcohol, bar snacks, snooker
A5: Kitchen | B5: Food ingredients, cooking supplies, kitchen water, kitchen equipment
A6: Utilities | B6: Generator fuel, DSTV/SLTV, electricity, internet/WiFi, water bill
A7: Maintenance | B7: Repairs (plumbing, electrical, AC), tools, painting, building fixes
A8: Salaries | B8: Staff wages, daily worker pay, security, housekeeping, stipends
A9: Supplies | B9: Soap, toiletries, cleaning products, tissue, detergent, consumables
A10: Other | B10: Bank charges, printing, transport, anything that doesn't fit above
A12: ── STATUS (AUTO) ── | B12: Calculated automatically — do not type in Status column
A13: Paid | B13: Amount Paid = Total Charged. Customer has settled in full.
A14: Part Payment | B14: Amount Paid > 0 but less than Total Charged. Balance still owed.
A15: Not Paid | B15: Amount Paid = 0. Customer has paid nothing yet.
A16: Overpaid | B16: Amount Paid > Total Charged. Customer paid more than charged.
